{"uuid": "492708c3-2044-4afb-9f6a-ed70c19ff057", "children": ["07328429-92f4-4091-8a7f-8d78c6fbbdd6"], "befores": [{"name": "setup_virtual_device", "status": "broken", "statusDetails": {"message": "selenium.common.exceptions.WebDriverException: Message: An unknown server-side error occurred while processing the command. Original error: Error getting AVD with retry. Original error: Condition unmet after 60070 ms. Timing out.\nStacktrace:\nUnknownError: An unknown server-side error occurred while processing the command. Original error: Error getting AVD with retry. Original error: Condition unmet after 60070 ms. Timing out.\n    at getResponseForW3CError (C:\\Users\\admin\\AppData\\Roaming\\npm\\node_modules\\appium\\node_modules\\appium-base-driver\\lib\\protocol\\errors.js:804:9)\n    at asyncHandler (C:\\Users\\admin\\AppData\\Roaming\\npm\\node_modules\\appium\\node_modules\\appium-base-driver\\lib\\protocol\\protocol.js:380:37)\n", "trace": "  File \"C:\\Users\\admin\\PycharmProjects\\pythonProject5\\venv\\Lib\\site-packages\\pluggy\\_callers.py\", line 77, in _multicall\n    res = hook_impl.function(*args)\n          ^^^^^^^^^^^^^^^^^^^^^^^^^\n  File \"C:\\Users\\admin\\PycharmProjects\\pythonProject5\\venv\\Lib\\site-packages\\_pytest\\fixtures.py\", line 1123, in pytest_fixture_setup\n    result = call_fixture_func(fixturefunc, request, kwargs)\n             ^^^^^^^^^^^^^^^^^^^^^^^^^^^^^^^^^^^^^^^^^^^^^^^\n  File \"C:\\Users\\admin\\PycharmProjects\\pythonProject5\\venv\\Lib\\site-packages\\_pytest\\fixtures.py\", line 902, in call_fixture_func\n    fixture_result = fixturefunc(**kwargs)\n                     ^^^^^^^^^^^^^^^^^^^^^\n  File \"C:\\Users\\admin\\PycharmProjects\\pythonProject5\\tests\\conftest.py\", line 58, in setup_virtual_device\n    request.instance.driver = webdriver.Remote(url, options=capabilities_options)\n                              ^^^^^^^^^^^^^^^^^^^^^^^^^^^^^^^^^^^^^^^^^^^^^^^^^^^\n  File \"C:\\Users\\admin\\PycharmProjects\\pythonProject5\\venv\\Lib\\site-packages\\appium\\webdriver\\webdriver.py\", line 229, in __init__\n    super().__init__(\n  File \"C:\\Users\\admin\\PycharmProjects\\pythonProject5\\venv\\Lib\\site-packages\\selenium\\webdriver\\remote\\webdriver.py\", line 205, in __init__\n    self.start_session(capabilities)\n  File \"C:\\Users\\admin\\PycharmProjects\\pythonProject5\\venv\\Lib\\site-packages\\appium\\webdriver\\webdriver.py\", line 318, in start_session\n    response = self.execute(RemoteCommand.NEW_SESSION, w3c_caps)\n               ^^^^^^^^^^^^^^^^^^^^^^^^^^^^^^^^^^^^^^^^^^^^^^^^^\n  File \"C:\\Users\\admin\\PycharmProjects\\pythonProject5\\venv\\Lib\\site-packages\\selenium\\webdriver\\remote\\webdriver.py\", line 344, in execute\n    self.error_handler.check_response(response)\n  File \"C:\\Users\\admin\\PycharmProjects\\pythonProject5\\venv\\Lib\\site-packages\\selenium\\webdriver\\remote\\errorhandler.py\", line 229, in check_response\n    raise exception_class(message, screen, stacktrace)\n"}, "start": 1701050126251, "stop": 1701050194985}], "afters": [{"name": "setup_virtual_device::stop", "status": "passed", "start": 1701050195469, "stop": 1701050195470}], "start": 1701050126251, "stop": 1701050195470}